2025-01-03 00:55:39,214 - ERROR - Ignoring exception in command 'list'
Traceback (most recent call last):
  File "/home/psg420/SMITE_v2/venv/lib/python3.11/site-packages/discord/app_commands/commands.py", line 857, in _do_call
    return await self._callback(self.binding, interaction, **params)  # type: ignore
           ^^^^^^^^^^^^^^^^^^^^^^^^^^^^^^^^^^^^^^^^^^^^^^^^^^^^^^^^^
  File "/home/psg420/SMITE_v2/cogs/transactioncog.py", line 25, in transaction_list
    message = await interaction.followup.send("Fetching your transactions...", view=view)
              ^^^^^^^^^^^^^^^^^^^^^^^^^^^^^^^^^^^^^^^^^^^^^^^^^^^^^^^^^^^^^^^^^^^^^^^^^^^
  File "/home/psg420/SMITE_v2/venv/lib/python3.11/site-packages/discord/webhook/async_.py", line 1843, in send
    data = await adapter.execute_webhook(
           ^^^^^^^^^^^^^^^^^^^^^^^^^^^^^^
  File "/home/psg420/SMITE_v2/venv/lib/python3.11/site-packages/discord/webhook/async_.py", line 221, in request
    raise NotFound(response, data)
discord.errors.NotFound: 404 Not Found (error code: 10015): Unknown Webhook

The above exception was the direct cause of the following exception:

Traceback (most recent call last):
  File "/home/psg420/SMITE_v2/venv/lib/python3.11/site-packages/discord/app_commands/tree.py", line 1310, in _call
    await command._invoke_with_namespace(interaction, namespace)
  File "/home/psg420/SMITE_v2/venv/lib/python3.11/site-packages/discord/app_commands/commands.py", line 883, in _invoke_with_namespace
    return await self._do_call(interaction, transformed_values)
           ^^^^^^^^^^^^^^^^^^^^^^^^^^^^^^^^^^^^^^^^^^^^^^^^^^^^
  File "/home/psg420/SMITE_v2/venv/lib/python3.11/site-packages/discord/app_commands/commands.py", line 876, in _do_call
    raise CommandInvokeError(self, e) from e
discord.app_commands.errors.CommandInvokeError: Command 'list' raised an exception: NotFound: 404 Not Found (error code: 10015): Unknown Webhook
